Workbook
Name CategoriasLista: 'CATALOGOS'!$A$5:$A$26
Name UnidadesLista: 'CATALOGOS'!$E$5:$E$14
Name ProveedoresLista: 'CATALOGOS'!$H$5:$H$14

Sheet INSTRUCCIONES
A1: FERREPRO · Inventario físico maestro
A2: Complete primero el catálogo y conteo. El barcode puede escanearse en una fase posterior.
A4: Cómo trabajar
A5: • Una fila representa un producto/SKU. No fusione variantes distintas.
A6: • No cambie encabezados ni borre registro_inventario_id o IDs técnicos.
A7: • Escriba el conteo físico en cantidad_contada; stock_sistema_actual es solo referencia.
A8: • Los precios y cantidades deben ser celdas numéricas, no texto.
A9: • cantidad_contada admite hasta 3 decimales; active permite_decimales para fracciones.
A10: • codigo_barras puede quedar vacío y estado_barcode debe permanecer PENDIENTE.
A11: • No duplique una fila porque un SKU tenga varios barcodes; códigos adicionales se modelarán después.
A12: • Use observaciones_inventario para presentaciones, ubicación o dudas.
A15: Flujo posterior
... A20: Leyenda
A21: OBLIGATORIO | B21: Debe existir para LISTO_SIN_BARCODE
A22: OPCIONAL | B22: Mejora la ficha pero no bloquea
A23: AUTOMÁTICO | B23: Fórmula o identidad técnica; no editar
A24: PENDIENTE BARCODE | B24: Se completa al escanear físicamente

Sheet PRODUCTOS
A1: PRODUCTOS · captura maestra
A2: Amarillo = obligatorio · gris = automático · morado = barcode posterior. cantidad_contada nunca se prellena desde stock.
A3: IDENTIFICACIÓN | M3: INFORMACIÓN COMERCIAL | U3: INVENTARIO FÍSICO | AA3: CÁLCULOS | AF3: BARCODE | AH3: CONTROL
A4: registro_inventario_id | B4: tipo_registro | C4: activo_sistema | D4: producto_id_sistema | E4: producto_local_id | F4: codigo_sistema_actual | G4: nombre | H4: categoria | I4: marca | J4: presentacion | K4: proveedor | L4: proveedor_id | M4: precio_compra | N4: precio_venta | O4: stock_minimo | P4: unidad_medida | Q4: permite_decimales | R4: viene_en_caja | S4: unidades_por_caja | T4: vende_por_empaque | U4: ubicacion | V4: descripcion | W4: stock_sistema_actual | X4: cantidad_contada | Y4: pasillo | Z4: estante | AA4: diferencia_unidades | AB4: valor_inventario_costo | AC4: valor_potencial_venta | AD4: margen_unitario | AE4: margen_porcentaje | AF4: codigo_barras | AG4: estado_barcode | AH4: estado_registro | AI4: errores_validacion | AJ4: observaciones_inventario | AK4: posible_duplicado
A5: 408d9794-eb9f-596a-91c2-04a55adc3295 | B5: EXISTENTE | C5: INACTIVO | D5: 1 | E5: 94c73223-e48e-48c3-a9c5-478abbc7e1c6 | G5: Rodillo de pintura | H5: Pinturas y Acabados | I5: marca 1 | K5: alexander | L5: 1 | M5: 12000 | N5: 77777 | O5: 10 | P5: UNIDAD | Q5: NO | R5: NO | S5: 1 | T5: NO | W5: 31 | AA5: =IF(X5="","",X5-IF(W5="",0,W5)) | AB5: =IF(OR(X5="",M5=""),"",X5*M5) | AC5: =IF(OR(X5="",N5=""),"",X5*N5) | AD5: =IF(OR(M5="",N5=""),"",N5-M5) | AE5: =IFERROR(IF(M5>0,(N5-M5)/M5,""),"") | AG5: PENDIENTE | AH5: =IF(NOT(OR(B5="EXISTENTE",COUNTA(G5,H5,I5,J5,K5,M5,N5,U5,V5,X5,Y5,Z5,AF5,AJ5)>0)),"",IF(AK5<>"","REVISAR",IF(OR(G5="",H5="",M5="",N5="",O5="",P5="",X5=""),"INCOMPLETO",IF(AI5<>"","REVISAR",IF(AND(AF5<>"",AG5="ESCANEADO"),"LISTO_COMPLETO","LISTO_SIN_BARCODE"))))) | AI5: =IF(NOT(OR(B5="EXISTENTE",COUNTA(G5,H5,I5,J5,K5,M5,N5,U5,V5,X5,Y5,Z5,AF5,AJ5)>0)),"",TEXTJOIN(" | ",TRUE,IF(A5="","Falta ID staging",""),IF(COUNTIF($A$5:$A$445,A5)>1,"ID staging duplicado",""),IF(G5="","Falta nombre",""),IF(LEN(G5)>150,"Nombre >150 caracteres",""),IF(H5="","Falta categoría",IF(COUNTIF(CategoriasLista,H5)=0,"Categoría inválida","")),IF(M5="","Falta precio compra",IF(OR(NOT(ISNUMBER(M5)),M5<0),"Precio compra inválido","")),IF(N5="","Falta precio venta",IF(OR(NOT(ISNUMBER(N5)),N5<=0,N5<M5),"Precio venta inválido","")),IF(O5="","Falta stock mínimo",IF(OR(NOT(ISNUMBER(O5)),O5<0,MOD(O5,1)<>0),"Stock mínimo inválido","")),IF(P5="","Falta unidad",IF(COUNTIF(UnidadesLista,P5)=0,"Unidad inválida","")),IF(AND(K5<>"",COUNTIF(ProveedoresLista,K5)=0),"Proveedor no catalogado",""),IF(X5="","Falta cantidad contada",IF(OR(NOT(ISNUMBER(X5)),X5<0,ABS(X5*1000-ROUND(X5*1000,0))>0.0000001),"Cantidad inválida",IF(AND(Q5="NO",MOD(X5,1)<>0),"Cantidad fraccionaria no permitida",""))),IF(AND(R5="SI",OR(NOT(ISNUMBER(S5)),S5<1,MOD(S5,1)<>0)),"Empaque inválido",""),IF(OR(AND(AF5="",AG5="ESCANEADO"),AND(AF5<>"",AG5<>"ESCANEADO")),"Barcode/estado inconsistente",""),IF(AK5<>"",AK5,""))) | AK5: =IF(G5="","",IF(OR(COUNTIFS($G$5:$G$445,G5,$I$5:$I$445,I5,$J$5:$J$445,J5,$P$5:$P$445,P5)>1,AND(AF5<>"",COUNTIF($AF$5:$AF$445,AF5)>1)),"REVISAR_POSIBLE_DUPLICADO",""))
A6: 25abc981-b644-5de8-8c18-0d9c68a254d6 | B6: EXISTENTE | C6: ACTIVO | D6: 2 | E6: 83f17ae0-d41e-4c5d-8cf5-aca39aa41723 | G6: martillo | H6: herramientas manuales | I6: tolima | K6: alexander | L6: 1 | M6: 5000 | N6: 12000 | O6: 10 | P6: CAJA | Q6: NO | R6: SI | S6: 24 | T6: NO | W6: 77 | AA6: =IF(X6="","",X6-IF(W6="",0,W6)) | AB6: =IF(OR(X6="",M6=""),"",X6*M6) | AC6: =IF(OR(X6="",N6=""),"",X6*N6) | AD6: =IF(OR(M6="",N6=""),"",N6-M6) | AE6: =IFERROR(IF(M6>0,(N6-M6)/M6,""),"") | AG6: PENDIENTE | AH6: =IF(NOT(OR(B6="EXISTENTE",COUNTA(G6,H6,I6,J6,K6,M6,N6,U6,V6,X6,Y6,Z6,AF6,AJ6)>0)),"",IF(AK6<>"","REVISAR",IF(OR(G6="",H6="",M6="",N6="",O6="",P6="",X6=""),"INCOMPLETO",IF(AI6<>"","REVISAR",IF(AND(AF6<>"",AG6="ESCANEADO"),"LISTO_COMPLETO","LISTO_SIN_BARCODE"))))) | AI6: =IF(NOT(OR(B6="EXISTENTE",COUNTA(G6,H6,I6,J6,K6,M6,N6,U6,V6,X6,Y6,Z6,AF6,AJ6)>0)),"",TEXTJOIN(" | ",TRUE,IF(A6="","Falta ID staging",""),IF(COUNTIF($A$5:$A$445,A6)>1,"ID staging duplicado",""),IF(G6="","Falta nombre",""),IF(LEN(G6)>150,"Nombre >150 caracteres",""),IF(H6="","Falta categoría",IF(COUNTIF(CategoriasLista,H6)=0,"Categoría inválida","")),IF(M6="","Falta precio compra",IF(OR(NOT(ISNUMBER(M6)),M6<0),"Precio compra inválido","")),IF(N6="","Falta precio venta",IF(OR(NOT(ISNUMBER(N6)),N6<=0,N6<M6),"Precio venta inválido","")),IF(O6="","Falta stock mínimo",IF(OR(NOT(ISNUMBER(O6)),O6<0,MOD(O6,1)<>0),"Stock mínimo inválido","")),IF(P6="","Falta unidad",IF(COUNTIF(UnidadesLista,P6)=0,"Unidad inválida","")),IF(AND(K6<>"",COUNTIF(ProveedoresLista,K6)=0),"Proveedor no catalogado",""),IF(X6="","Falta cantidad contada",IF(OR(NOT(ISNUMBER(X6)),X6<0,ABS(X6*1000-ROUND(X6*1000,0))>0.0000001),"Cantidad inválida",IF(AND(Q6="NO",MOD(X6,1)<>0),"Cantidad fraccionaria no permitida",""))),IF(AND(R6="SI",OR(NOT(ISNUMBER(S6)),S6<1,MOD(S6,1)<>0)),"Empaque inválido",""),IF(OR(AND(AF6="",AG6="ESCANEADO"),AND(AF6<>"",AG6<>"ESCANEADO")),"Barcode/estado inconsistente",""),IF(AK6<>"",AK6,""))) | AK6: =IF(G6="","",IF(OR(COUNTIFS($G$5:$G$445,G6,$I$5:$I$445,I6,$J$5:$J$445,J6,$P$5:$P$445,P6)>1,AND(AF6<>"",COUNTIF($AF$5:$AF$445,AF6)>1)),"REVISAR_POSIBLE_DUPLICADO",""))
A7: 3abdaba8-410e-596e-a979-91b84038ce4f | B7: EXISTENTE | C7: ACTIVO | D7: 3 | E7: 9afd3836-b303-4aba-8960-3a3e38ff04bd | G7: cincele | H7: herramientas manuales | I7: tolima | K7: alexander | L7: 1 | M7: 10000 | N7: 15000 | O7: 10 | P7: CAJA | Q7: NO | R7: SI | S7: 10 | T7: NO | W7: 153 | AA7: =IF(X7="","",X7-IF(W7="",0,W7)) | AB7: =IF(OR(X7="",M7=""),"",X7*M7) | AC7: =IF(OR(X7="",N7=""),"",X7*N7) | AD7: =IF(OR(M7="",N7=""),"",N7-M7) | AE7: =IFERROR(IF(M7>0,(N7-M7)/M7,""),"") | AG7: PENDIENTE | AH7: =IF(NOT(OR(B7="EXISTENTE",COUNTA(G7,H7,I7,J7,K7,M7,N7,U7,V7,X7,Y7,Z7,AF7,AJ7)>0)),"",IF(AK7<>"","REVISAR",IF(OR(G7="",H7="",M7="",N7="",O7="",P7="",X7=""),"INCOMPLETO",IF(AI7<>"","REVISAR",IF(AND(AF7<>"",AG7="ESCANEADO"),"LISTO_COMPLETO","LISTO_SIN_BARCODE"))))) | AI7: =IF(NOT(OR(B7="EXISTENTE",COUNTA(G7,H7,I7,J7,K7,M7,N7,U7,V7,X7,Y7,Z7,AF7,AJ7)>0)),"",TEXTJOIN(" | ",TRUE,IF(A7="","Falta ID staging",""),IF(COUNTIF($A$5:$A$445,A7)>1,"ID staging duplicado",""),IF(G7="","Falta nombre",""),IF(LEN(G7)>150,"Nombre >150 caracteres",""),IF(H7="","Falta categoría",IF(COUNTIF(CategoriasLista,H7)=0,"Categoría inválida","")),IF(M7="","Falta precio compra",IF(OR(NOT(ISNUMBER(M7)),M7<0),"Precio compra inválido","")),IF(N7="","Falta precio venta",IF(OR(NOT(ISNUMBER(N7)),N7<=0,N7<M7),"Precio venta inválido","")),IF(O7="","Falta stock mínimo",IF(OR(NOT(ISNUMBER(O7)),O7<0,MOD(O7,1)<>0),"Stock mínimo inválido","")),IF(P7="","Falta unidad",IF(COUNTIF(UnidadesLista,P7)=0,"Unidad inválida","")),IF(AND(K7<>"",COUNTIF(ProveedoresLista,K7)=0),"Proveedor no catalogado",""),IF(X7="","Falta cantidad contada",IF(OR(NOT(ISNUMBER(X7)),X7<0,ABS(X7*1000-ROUND(X7*1000,0))>0.0000001),"Cantidad inválida",IF(AND(Q7="NO",MOD(X7,1)<>0),"Cantidad fraccionaria no permitida",""))),IF(AND(R7="SI",OR(NOT(ISNUMBER(S7)),S7<1,MOD(S7,1)<>0)),"Empaque inválido",""),IF(OR(AND(AF7="",AG7="ESCANEADO"),AND(AF7<>"",AG7<>"ESCANEADO")),"Barcode/estado inconsistente",""),IF(AK7<>"",AK7,""))) | AK7: =IF(G7="","",IF(OR(COUNTIFS($G$5:$G$445,G7,$I$5:$I$445,I7,$J$5:$J$445,J7,$P$5:$P$445,P7)>1,AND(AF7<>"",COUNTIF($AF$5:$AF$445,AF7)>1)),"REVISAR_POSIBLE_DUPLICADO",""))
A8: 237c1b6c-8006-5863-8778-978fbaa9202c | B8: EXISTENTE | C8: ACTIVO | D8: 4 | E8: a0c5f90d-9b36-42a3-bb1a-257c19b9411d | G8: rodillo de pintura 4'' | H8: Pinturas y Acabados | I8: marca 1 | K8: alexander | L8: 1 | M8: 3500 | N8: 7000 | O8: 10 | P8: UNIDAD | Q8: NO | R8: SI | S8: 2 | T8: NO | W8: 12 | AA8: =IF(X8="","",X8-IF(W8="",0,W8)) | AB8: =IF(OR(X8="",M8=""),"",X8*M8) | AC8: =IF(OR(X8="",N8=""),"",X8*N8) | AD8: =IF(OR(M8="",N8=""),"",N8-M8) | AE8: =IFERROR(IF(M8>0,(N8-M8)/M8,""),"") | AG8: PENDIENTE | AH8: =IF(NOT(OR(B8="EXISTENTE",COUNTA(G8,H8,I8,J8,K8,M8,N8,U8,V8,X8,Y8,Z8,AF8,AJ8)>0)),"",IF(AK8<>"","REVISAR",IF(OR(G8="",H8="",M8="",N8="",O8="",P8="",X8=""),"INCOMPLETO",IF(AI8<>"","REVISAR",IF(AND(AF8<>"",AG8="ESCANEADO"),"LISTO_COMPLETO","LISTO_SIN_BARCODE"))))) | AI8: =IF(NOT(OR(B8="EXISTENTE",COUNTA(G8,H8,I8,J8,K8,M8,N8,U8,V8,X8,Y8,Z8,AF8,AJ8)>0)),"",TEXTJOIN(" | ",TRUE,IF(A8="","Falta ID staging",""),IF(COUNTIF($A$5:$A$445,A8)>1,"ID staging duplicado",""),IF(G8="","Falta nombre",""),IF(LEN(G8)>150,"Nombre >150 caracteres",""),IF(H8="","Falta categoría",IF(COUNTIF(CategoriasLista,H8)=0,"Categoría inválida","")),IF(M8="","Falta precio compra",IF(OR(NOT(ISNUMBER(M8)),M8<0),"Precio compra inválido","")),IF(N8="","Falta precio venta",IF(OR(NOT(ISNUMBER(N8)),N8<=0,N8<M8),"Precio venta inválido","")),IF(O8="","Falta stock mínimo",IF(OR(NOT(ISNUMBER(O8)),O8<0,MOD(O8,1)<>0),"Stock mínimo inválido","")),IF(P8="","Falta unidad",IF(COUNTIF(UnidadesLista,P8)=0,"Unidad inválida","")),IF(AND(K8<>"",COUNTIF(ProveedoresLista,K8)=0),"Proveedor no catalogado",""),IF(X8="","Falta cantidad contada",IF(OR(NOT(ISNUMBER(X8)),X8<0,ABS(X8*1000-ROUND(X8*1000,0))>0.0000001),"Cantidad inválida",IF(AND(Q8="NO",MOD(X8,1)<>0),"Cantidad fraccionaria no permitida",""))),IF(AND(R8="SI",OR(NOT(ISNUMBER(S8)),S8<1,MOD(S8,1)<>0)),"Empaque inválido",""),IF(OR(AND(AF8="",AG8="ESCANEADO"),AND(AF8<>"",AG8<>"ESCANEADO")),"Barcode/estado inconsistente",""),IF(AK8<>"",AK8,""))) | AK8: =IF(G8="","",IF(OR(COUNTIFS($G$5:$G$445,G8,$I$5:$I$445,I8,$J$5:$J$445,J8,$P$5:$P$445,P8)>1,AND(AF8<>"",COUNTIF($AF$5:$AF$445,AF8)>1)),"REVISAR_POSIBLE_DUPLICADO",""))
A9: 7b460357-613a-502d-969d-98bc62fd3a34 | B9: EXISTENTE | C9: ACTIVO | D9: 5 | E9: 55ccca74-53f2-43e4-bc6a-b742f5c81cb7 | F9: CLV3P001 | G9: Clavos 3 pulgadas | H9: Ferretería | I9: Generic | M9: 100 | N9: 350 | O9: 100 | P9: UNIDAD | Q9: NO | R9: SI | S9: 50 | T9: SI | W9: 12 | AA9: =IF(X9="","",X9-IF(W9="",0,W9)) | AB9: =IF(OR(X9="",M9=""),"",X9*M9) | AC9: =IF(OR(X9="",N9=""),"",X9*N9) | AD9: =IF(OR(M9="",N9=""),"",N9-M9) | AE9: =IFERROR(IF(M9>0,(N9-M9)/M9,""),"") | AG9: PENDIENTE | AH9: =IF(NOT(OR(B9="EXISTENTE",COUNTA(G9,H9,I9,J9,K9,M9,N9,U9,V9,X9,Y9,Z9,AF9,AJ9)>0)),"",IF(AK9<>"","REVISAR",IF(OR(G9="",H9="",M9="",N9="",O9="",P9="",X9=""),"INCOMPLETO",IF(AI9<>"","REVISAR",IF(AND(AF9<>"",AG9="ESCANEADO"),"LISTO_COMPLETO","LISTO_SIN_BARCODE"))))) | AI9: =IF(NOT(OR(B9="EXISTENTE",COUNTA(G9,H9,I9,J9,K9,M9,N9,U9,V9,X9,Y9,Z9,AF9,AJ9)>0)),"",TEXTJOIN(" | ",TRUE,IF(A9="","Falta ID staging",""),IF(COUNTIF($A$5:$A$445,A9)>1,"ID staging duplicado",""),IF(G9="","Falta nombre",""),IF(LEN(G9)>150,"Nombre >150 caracteres",""),IF(H9="","Falta categoría",IF(COUNTIF(CategoriasLista,H9)=0,"Categoría inválida","")),IF(M9="","Falta precio compra",IF(OR(NOT(ISNUMBER(M9)),M9<0),"Precio compra inválido","")),IF(N9="","Falta precio venta",IF(OR(NOT(ISNUMBER(N9)),N9<=0,N9<M9),"Precio venta inválido","")),IF(O9="","Falta stock mínimo",IF(OR(NOT(ISNUMBER(O9)),O9<0,MOD(O9,1)<>0),"Stock mínimo inválido","")),IF(P9="","Falta unidad",IF(COUNTIF(UnidadesLista,P9)=0,"Unidad inválida","")),IF(AND(K9<>"",COUNTIF(ProveedoresLista,K9)=0),"Proveedor no catalogado",""),IF(X9="","Falta cantidad contada",IF(OR(NOT(ISNUMBER(X9)),X9<0,ABS(X9*1000-ROUND(X9*1000,0))>0.0000001),"Cantidad inválida",IF(AND(Q9="NO",MOD(X9,1)<>0),"Cantidad fraccionaria no permitida",""))),IF(AND(R9="SI",OR(NOT(ISNUMBER(S9)),S9<1,MOD(S9,1)<>0)),"Empaque inválido",""),IF(OR(AND(AF9="",AG9="ESCANEADO"),AND(AF9<>"",AG9<>"ESCANEADO")),"Barcode/estado inconsistente",""),IF(AK9<>"",AK9,""))) | AK9: =IF(G9="","",IF(OR(COUNTIFS($G$5:$G$445,G9,$I$5:$I$445,I9,$J$5:$J$445,J9,$P$5:$P$445,P9)>1,AND(AF9<>"",COUNTIF($AF$5:$AF$445,AF9)>1)),"REVISAR_POSIBLE_DUPLICADO",""))
A10: d1e45b75-e5e8-5d83-9fce-e83086892f19 | B10: EXISTENTE | C10: ACTIVO | D10: 6 | E10: e66f381c-adab-4d12-befc-0ab28b5f27a6 | G10: pintura T1 Blanca | H10: Pinturas | I10: getics | K10: juan | L10: 2 | M10: 40000 | N10: 65000 | O10: 4 | P10: UNIDAD | Q10: SI | R10: NO | S10: 1 | T10: NO | W10: 3 | AA10: =IF(X10="","",X10-IF(W10="",0,W10)) | AB10: =IF(OR(X10="",M10=""),"",X10*M10) | AC10: =IF(OR(X10="",N10=""),"",X10*N10) | AD10: =IF(OR(M10="",N10=""),"",N10-M10) | AE10: =IFERROR(IF(M10>0,(N10-M10)/M10,""),"") | AG10: PENDIENTE | AH10: =IF(NOT(OR(B10="EXISTENTE",COUNTA(G10,H10,I10,J10,K10,M10,N10,U10,V10,X10,Y10,Z10,AF10,AJ10)>0)),"",IF(AK10<>"","REVISAR",IF(OR(G10="",H10="",M10="",N10="",O10="",P10="",X10=""),"INCOMPLETO",IF(AI10<>"","REVISAR",IF(AND(AF10<>"",AG10="ESCANEADO"),"LISTO_COMPLETO","LISTO_SIN_BARCODE"))))) | AI10: =IF(NOT(OR(B10="EXISTENTE",COUNTA(G10,H10,I10,J10,K10,M10,N10,U10,V10,X10,Y10,Z10,AF10,AJ10)>0)),"",TEXTJOIN(" | ",TRUE,IF(A10="","Falta ID staging",""),IF(COUNTIF($A$5:$A$445,A10)>1,"ID staging duplicado",""),IF(G10="","Falta nombre",""),IF(LEN(G10)>150,"Nombre >150 caracteres",""),IF(H10="","Falta categoría",IF(COUNTIF(CategoriasLista,H10)=0,"Categoría inválida","")),IF(M10="","Falta precio compra",IF(OR(NOT(ISNUMBER(M10)),M10<0),"Precio compra inválido","")),IF(N10="","Falta precio venta",IF(OR(NOT(ISNUMBER(N10)),N10<=0,N10<M10),"Precio venta inválido","")),IF(O10="","Falta stock mínimo",IF(OR(NOT(ISNUMBER(O10)),O10<0,MOD(O10,1)<>0),"Stock mínimo inválido","")),IF(P10="","Falta unidad",IF(COUNTIF(UnidadesLista,P10)=0,"Unidad inválida","")),IF(AND(K10<>"",COUNTIF(ProveedoresLista,K10)=0),"Proveedor no catalogado",""),IF(X10="","Falta cantidad contada",IF(OR(NOT(ISNUMBER(X10)),X10<0,ABS(X10*1000-ROUND(X10*1000,0))>0.0000001),"Cantidad inválida",IF(AND(Q10="NO",MOD(X10,1)<>0),"Cantidad fraccionaria no permitida",""))),IF(AND(R10="SI",OR(NOT(ISNUMBER(S10)),S10<1,MOD(S10,1)<>0)),"Empaque inválido",""),IF(OR(AND(AF10="",AG10="ESCANEADO"),AND(AF10<>"",AG10<>"ESCANEADO")),"Barcode/estado inconsistente",""),IF(AK10<>"",AK10,""))) | AK10: =IF(G10="","",IF(OR(COUNTIFS($G$5:$G$445,G10,$I$5:$I$445,I10,$J$5:$J$445,J10,$P$5:$P$445,P10)>1,AND(AF10<>"",COUNTIF($AF$5:$AF$445,AF10)>1)),"REVISAR_POSIBLE_DUPLICADO",""))
A11: 4ef6bcdb-77b3-542d-86ca-7cb0b96fc4af | B11: EXISTENTE | C11: ACTIVO | D11: 7 | E11: 511cc3eb-753d-4667-b5e7-2c471208d127 | G11: Rodillo de pintura | H11: Herramientas Manuales | I11: getics | K11: alexander | L11: 1 | M11: 10000 | N11: 17000 | O11: 6 | P11: UNIDAD | Q11: NO | R11: SI | S11: 2 | T11: NO | W11: 0 | AA11: =IF(X11="","",X11-IF(W11="",0,W11)) | AB11: =IF(OR(X11="",M11=""),"",X11*M11) | AC11: =IF(OR(X11="",N11=""),"",X11*N11) | AD11: =IF(OR(M11="",N11=""),"",N11-M11) | AE11: =IFERROR(IF(M11>0,(N11-M11)/M11,""),"") | AG11: PENDIENTE | AH11: =IF(NOT(OR(B11="EXISTENTE",COUNTA(G11,H11,I11,J11,K11,M11,N11,U11,V11,X11,Y11,Z11,AF11,AJ11)>0)),"",IF(AK11<>"","REVISAR",IF(OR(G11="",H11="",M11="",N11="",O11="",P11="",X11=""),"INCOMPLETO",IF(AI11<>"","REVISAR",IF(AND(AF11<>"",AG11="ESCANEADO"),"LISTO_COMPLETO","LISTO_SIN_BARCODE"))))) | AI11: =IF(NOT(OR(B11="EXISTENTE",COUNTA(G11,H11,I11,J11,K11,M11,N11,U11,V11,X11,Y11,Z11,AF11,AJ11)>0)),"",TEXTJOIN(" | ",TRUE,IF(A11="","Falta ID staging",""),IF(COUNTIF($A$5:$A$445,A11)>1,"ID staging duplicado",""),IF(G11="","Falta nombre",""),IF(LEN(G11)>150,"Nombre >150 caracteres",""),IF(H11="","Falta categoría",IF(COUNTIF(CategoriasLista,H11)=0,"Categoría inválida","")),IF(M11="","Falta precio compra",IF(OR(NOT(ISNUMBER(M11)),M11<0),"Precio compra inválido","")),IF(N11="","Falta precio venta",IF(OR(NOT(ISNUMBER(N11)),N11<=0,N11<M11),"Precio venta inválido","")),IF(O11="","Falta stock mínimo",IF(OR(NOT(ISNUMBER(O11)),O11<0,MOD(O11,1)<>0),"Stock mínimo inválido","")),IF(P11="","Falta unidad",IF(COUNTIF(UnidadesLista,P11)=0,"Unidad inválida","")),IF(AND(K11<>"",COUNTIF(ProveedoresLista,K11)=0),"Proveedor no catalogado",""),IF(X11="","Falta cantidad contada",IF(OR(NOT(ISNUMBER(X11)),X11<0,ABS(X11*1000-ROUND(X11*1000,0))>0.0000001),"Cantidad inválida",IF(AND(Q11="NO",MOD(X11,1)<>0),"Cantidad fraccionaria no permitida",""))),IF(AND(R11="SI",OR(NOT(ISNUMBER(S11)),S11<1,MOD(S11,1)<>0)),"Empaque inválido",""),IF(OR(AND(AF11="",AG11="ESCANEADO"),AND(AF11<>"",AG11<>"ESCANEADO")),"Barcode/estado inconsistente",""),IF(AK11<>"",AK11,""))) | AK11: =IF(G11="","",IF(OR(COUNTIFS($G$5:$G$445,G11,$I$5:$I$445,I11,$J$5:$J$445,J11,$P$5:$P$445,P11)>1,AND(AF11<>"",COUNTIF($AF$5:$AF$445,AF11)>1)),"REVISAR_POSIBLE_DUPLICADO",""))
A12: a12c1f93-8429-503d-9b72-5ef545c0c555 | B12: EXISTENTE | C12: ACTIVO | D12: 8 | E12: 2a822014-df43-4342-9116-3c8fcac40f73 | G12: clavos 4 pulgadas | H12: Herrajes | I12: marca 1 | K12: alexander | L12: 1 | M12: 250 | N12: 400 | O12: 20 | P12: UNIDAD | Q12: NO | R12: SI | S12: 50 | T12: SI | W12: 1050 | AA12: =IF(X12="","",X12-IF(W12="",0,W12)) | AB12: =IF(OR(X12="",M12=""),"",X12*M12) | AC12: =IF(OR(X12="",N12=""),"",X12*N12) | AD12: =IF(OR(M12="",N12=""),"",N12-M12) | AE12: =IFERROR(IF(M12>0,(N12-M12)/M12,""),"") | AG12: PENDIENTE | AH12: =IF(NOT(OR(B12="EXISTENTE",COUNTA(G12,H12,I12,J12,K12,M12,N12,U12,V12,X12,Y12,Z12,AF12,AJ12)>0)),"",IF(AK12<>"","REVISAR",IF(OR(G12="",H12="",M12="",N12="",O12="",P12="",X12=""),"INCOMPLETO",IF(AI12<>"","REVISAR",IF(AND(AF12<>"",AG12="ESCANEADO"),"LISTO_COMPLETO","LISTO_SIN_BARCODE"))))) | AI12: =IF(NOT(OR(B12="EXISTENTE",COUNTA(G12,H12,I12,J12,K12,M12,N12,U12,V12,X12,Y12,Z12,AF12,AJ12)>0)),"",TEXTJOIN(" | ",TRUE,IF(A12="","Falta ID staging",""),IF(COUNTIF($A$5:$A$445,A12)>1,"ID staging duplicado",""),IF(G12="","Falta nombre",""),IF(LEN(G12)>150,"Nombre >150 caracteres",""),IF(H12="","Falta categoría",IF(COUNTIF(CategoriasLista,H12)=0,"Categoría inválida","")),IF(M12="","Falta precio compra",IF(OR(NOT(ISNUMBER(M12)),M12<0),"Precio compra inválido","")),IF(N12="","Falta precio venta",IF(OR(NOT(ISNUMBER(N12)),N12<=0,N12<M12),"Precio venta inválido","")),IF(O12="","Falta stock mínimo",IF(OR(NOT(ISNUMBER(O12)),O12<0,MOD(O12,1)<>0),"Stock mínimo inválido","")),IF(P12="","Falta unidad",IF(COUNTIF(UnidadesLista,P12)=0,"Unidad inválida","")),IF(AND(K12<>"",COUNTIF(ProveedoresLista,K12)=0),"Proveedor no catalogado",""),IF(X12="","Falta cantidad contada",IF(OR(NOT(ISNUMBER(X12)),X12<0,ABS(X12*1000-ROUND(X12*1000,0))>0.0000001),"Cantidad inválida",IF(AND(Q12="NO",MOD(X12,1)<>0),"Cantidad fraccionaria no permitida",""))),IF(AND(R12="SI",OR(NOT(ISNUMBER(S12)),S12<1,MOD(S12,1)<>0)),"Empaque inválido",""),IF(OR(AND(AF12="",AG12="ESCANEADO"),AND(AF12<>"",AG12<>"ESCANEADO")),"Barcode/estado inconsistente",""),IF(AK12<>"",AK12,""))) | AK12: =IF(G12="","",IF(OR(COUNTIFS($G$5:$G$445,G12,$I$5:$I$445,I12,$J$5:$J$445,J12,$P$5:$P$445,P12)>1,AND(AF12<>"",COUNTIF($AF$5:$AF$445,AF12)>1)),"REVISAR_POSIBLE_DUPLICADO",""))
A13: 01418194-bf88-5dc6-9566-08a5c627bc33 | B13: EXISTENTE | C13: ACTIVO | D13: 9 | E13: f637e98a-5418-42e9-b53b-fe73649b303f | G13: pintura blanca | H13: Pinturas | I13: onef | K13: alexander | L13: 1 | M13: 50000 | N13: 65000 | O13: 10 | P13: UNIDAD | Q13: NO | R13: SI | S13: 4 | T13: NO | W13: 18 | AA13: =IF(X13="","",X13-IF(W13="",0,W13)) | AB13: =IF(OR(X13="",M13=""),"",X13*M13) | AC13: =IF(OR(X13="",N13=""),"",X13*N13) | AD13: =IF(OR(M13="",N13=""),"",N13-M13) | AE13: =IFERROR(IF(M13>0,(N13-M13)/M13,""),"") | AG13: PENDIENTE | AH13: =IF(NOT(OR(B13="EXISTENTE",COUNTA(G13,H13,I13,J13,K13,M13,N13,U13,V13,X13,Y13,Z13,AF13,AJ13)>0)),"",IF(AK13<>"","REVISAR",IF(OR(G13="",H13="",M13="",N13="",O13="",P13="",X13=""),"INCOMPLETO",IF(AI13<>"","REVISAR",IF(AND(AF13<>"",AG13="ESCANEADO"),"LISTO_COMPLETO","LISTO_SIN_BARCODE"))))) | AI13: =IF(NOT(OR(B13="EXISTENTE",COUNTA(G13,H13,I13,J13,K13,M13,N13,U13,V13,X13,Y13,Z13,AF13,AJ13)>0)),"",TEXTJOIN(" | ",TRUE,IF(A13="","Falta ID staging",""),IF(COUNTIF($A$5:$A$445,A13)>1,"ID staging duplicado",""),IF(G13="","Falta nombre",""),IF(LEN(G13)>150,"Nombre >150 caracteres",""),IF(H13="","Falta categoría",IF(COUNTIF(CategoriasLista,H13)=0,"Categoría inválida","")),IF(M13="","Falta precio compra",IF(OR(NOT(ISNUMBER(M13)),M13<0),"Precio compra inválido","")),IF(N13="","Falta precio venta",IF(OR(NOT(ISNUMBER(N13)),N13<=0,N13<M13),"Precio venta inválido","")),IF(O13="","Falta stock mínimo",IF(OR(NOT(ISNUMBER(O13)),O13<0,MOD(O13,1)<>0),"Stock mínimo inválido","")),IF(P13="","Falta unidad",IF(COUNTIF(UnidadesLista,P13)=0,"Unidad inválida","")),IF(AND(K13<>"",COUNTIF(ProveedoresLista,K13)=0),"Proveedor no catalogado",""),IF(X13="","Falta cantidad contada",IF(OR(NOT(ISNUMBER(X13)),X13<0,ABS(X13*1000-ROUND(X13*1000,0))>0.0000001),"Cantidad inválida",IF(AND(Q13="NO",MOD(X13,1)<>0),"Cantidad fraccionaria no permitida",""))),IF(AND(R13="SI",OR(NOT(ISNUMBER(S13)),S13<1,MOD(S13,1)<>0)),"Empaque inválido",""),IF(OR(AND(AF13="",AG13="ESCANEADO"),AND(AF13<>"",AG13<>"ESCANEADO")),"Barcode/estado inconsistente",""),IF(AK13<>"",AK13,""))) | AK13: =IF(G13="","",IF(OR(COUNTIFS($G$5:$G$445,G13,$I$5:$I$445,I13,$J$5:$J$445,J13,$P$5:$P$445,P13)>1,AND(AF13<>"",COUNTIF($AF$5:$AF$445,AF13)>1)),"REVISAR_POSIBLE_DUPLICADO",""))
A14: 0b3087a9-709c-5aea-9780-98b264231626 | B14: EXISTENTE | C14: ACTIVO | D14: 10 | E14: 0593b78c-d651-4e36-8e51-ddebc0dadd10 | G14: pintura roja | H14: Pinturas | I14: onef | K14: juan | L14: 2 | M14: 50000 | N14: 65000 | O14: 10 | P14: UNIDAD | Q14: NO | R14: SI | S14: 4 | T14: NO | W14: 17 | AA14: =IF(X14="","",X14-IF(W14="",0,W14)) | AB14: =IF(OR(X14="",M14=""),"",X14*M14) | AC14: =IF(OR(X14="",N14=""),"",X14*N14) | AD14: =IF(OR(M14="",N14=""),"",N14-M14) | AE14: =IFERROR(IF(M14>0,(N14-M14)/M14,""),"") | AG14: PENDIENTE | AH14: =IF(NOT(OR(B14="EXISTENTE",COUNTA(G14,H14,I14,J14,K14,M14,N14,U14,V14,X14,Y14,Z14,AF14,AJ14)>0)),"",IF(AK14<>"","REVISAR",IF(OR(G14="",H14="",M14="",N14="",O14="",P14="",X14=""),"INCOMPLETO",IF(AI14<>"","REVISAR",IF(AND(AF14<>"",AG14="ESCANEADO"),"LISTO_COMPLETO","LISTO_SIN_BARCODE"))))) | AI14: =IF(NOT(OR(B14="EXISTENTE",COUNTA(G14,H14,I14,J14,K14,M14,N14,U14,V14,X14,Y14,Z14,AF14,AJ14)>0)),"",TEXTJOIN(" | ",TRUE,IF(A14="","Falta ID staging",""),IF(COUNTIF($A$5:$A$445,A14)>1,"ID staging duplicado",""),IF(G14="","Falta nombre",""),IF(LEN(G14)>150,"Nombre >150 caracteres",""),IF(H14="","Falta categoría",IF(COUNTIF(CategoriasLista,H14)=0,"Categoría inválida","")),IF(M14="","Falta precio compra",IF(OR(NOT(ISNUMBER(M14)),M14<0),"Precio compra inválido","")),IF(N14="","Falta precio venta",IF(OR(NOT(ISNUMBER(N14)),N14<=0,N14<M14),"Precio venta inválido","")),IF(O14="","Falta stock mínimo",IF(OR(NOT(ISNUMBER(O14)),O14<0,MOD(O14,1)<>0),"Stock mínimo inválido","")),IF(P14="","Falta unidad",IF(COUNTIF(UnidadesLista,P14)=0,"Unidad inválida","")),IF(AND(K14<>"",COUNTIF(ProveedoresLista,K14)=0),"Proveedor no catalogado",""),IF(X14="","Falta cantidad contada",IF(OR(NOT(ISNUMBER(X14)),X14<0,ABS(X14*1000-ROUND(X14*1000,0))>0.0000001),"Cantidad inválida",IF(AND(Q14="NO",MOD(X14,1)<>0),"Cantidad fraccionaria no permitida",""))),IF(AND(R14="SI",OR(NOT(ISNUMBER(S14)),S14<1,MOD(S14,1)<>0)),"Empaque inválido",""),IF(OR(AND(AF14="",AG14="ESCANEADO"),AND(AF14<>"",AG14<>"ESCANEADO")),"Barcode/estado inconsistente",""),IF(AK14<>"",AK14,""))) | AK14: =IF(G14="","",IF(OR(COUNTIFS($G$5:$G$445,G14,$I$5:$I$445,I14,$J$5:$J$445,J14,$P$5:$P$445,P14)>1,AND(AF14<>"",COUNTIF($AF$5:$AF$445,AF14)>1)),"REVISAR_POSIBLE_DUPLICADO",""))
A15: 29b0886c-2bbf-59e1-be07-7f7b05edb66e | B15: EXISTENTE | C15: ACTIVO | D15: 11 | E15: c86bcfac-0916-4ce0-ad7f-8603815dc68c | G15: Pintura T1 blanca | H15: Pinturas | I15: onef | K15: alexander | L15: 1 | M15: 40000 | N15: 60000 | O15: 4 | P15: LITRO | Q15: SI | R15: SI | S15: 1 | T15: NO | W15: 24 | AA15: =IF(X15="","",X15-IF(W15="",0,W15)) | AB15: =IF(OR(X15="",M15=""),"",X15*M15) | AC15: =IF(OR(X15="",N15=""),"",X15*N15) | AD15: =IF(OR(M15="",N15=""),"",N15-M15) | AE15: =IFERROR(IF(M15>0,(N15-M15)/M15,""),"") | AG15: PENDIENTE | AH15: =IF(NOT(OR(B15="EXISTENTE",COUNTA(G15,H15,I15,J15,K15,M15,N15,U15,V15,X15,Y15,Z15,AF15,AJ15)>0)),"",IF(AK15<>"","REVISAR",IF(OR(G15="",H15="",M15="",N15="",O15="",P15="",X15=""),"INCOMPLETO",IF(AI15<>"","REVISAR",IF(AND(AF15<>"",AG15="ESCANEADO"),"LISTO_COMPLETO","LISTO_SIN_BARCODE"))))) | AI15: =IF(NOT(OR(B15="EXISTENTE",COUNTA(G15,H15,I15,J15,K15,M15,N15,U15,V15,X15,Y15,Z15,AF15,AJ15)>0)),"",TEXTJOIN(" | ",TRUE,IF(A15="","Falta ID staging",""),IF(COUNTIF($A$5:$A$445,A15)>1,"ID staging duplicado",""),IF(G15="","Falta nombre",""),IF(LEN(G15)>150,"Nombre >150 caracteres",""),IF(H15="","Falta categoría",IF(COUNTIF(CategoriasLista,H15)=0,"Categoría inválida","")),IF(M15="","Falta precio compra",IF(OR(NOT(ISNUMBER(M15)),M15<0),"Precio compra inválido","")),IF(N15="","Falta precio venta",IF(OR(NOT(ISNUMBER(N15)),N15<=0,N15<M15),"Precio venta inválido","")),IF(O15="","Falta stock mínimo",IF(OR(NOT(ISNUMBER(O15)),O15<0,MOD(O15,1)<>0),"Stock mínimo inválido","")),IF(P15="","Falta unidad",IF(COUNTIF(UnidadesLista,P15)=0,"Unidad inválida","")),IF(AND(K15<>"",COUNTIF(ProveedoresLista,K15)=0),"Proveedor no catalogado",""),IF(X15="","Falta cantidad contada",IF(OR(NOT(ISNUMBER(X15)),X15<0,ABS(X15*1000-ROUND(X15*1000,0))>0.0000001),"Cantidad inválida",IF(AND(Q15="NO",MOD(X15,1)<>0),"Cantidad fraccionaria no permitida",""))),IF(AND(R15="SI",OR(NOT(ISNUMBER(S15)),S15<1,MOD(S15,1)<>0)),"Empaque inválido",""),IF(OR(AND(AF15="",AG15="ESCANEADO"),AND(AF15<>"",AG15<>"ESCANEADO")),"Barcode/estado inconsistente",""),IF(AK15<>"",AK15,""))) | AK15: =IF(G15="","",IF(OR(COUNTIFS($G$5:$G$445,G15,$I$5:$I$445,I15,$J$5:$J$445,J15,$P$5:$P$445,P15)>1,AND(AF15<>"",COUNTIF($AF$5:$AF$445,AF15)>1)),"REVISAR_POSIBLE_DUPLICADO",""))
A16: 234750bc-da4a-5b03-89be-515cd9598dc9 | B16: EXISTENTE | C16: ACTIVO | D16: 12 | E16: 4cc7b324-7f48-4eeb-b54d-6ced7e7f14f1 | G16: destornillador | H16: Herramientas Manuales | I16: Generic | K16: alexander | L16: 1 | M16: 7000 | N16: 10000 | O16: 10 | P16: UNIDAD | Q16: NO | R16: SI | S16: 10 | T16: NO | W16: 29 | AA16: =IF(X16="","",X16-IF(W16="",0,W16)) | AB16: =IF(OR(X16="",M16=""),"",X16*M16) | AC16: =IF(OR(X16="",N16=""),"",X16*N16) | AD16: =IF(OR(M16="",N16=""),"",N16-M16) | AE16: =IFERROR(IF(M16>0,(N16-M16)/M16,""),"") | AG16: PENDIENTE | AH16: =IF(NOT(OR(B16="EXISTENTE",COUNTA(G16,H16,I16,J16,K16,M16,N16,U16,V16,X16,Y16,Z16,AF16,AJ16)>0)),"",IF(AK16<>"","REVISAR",IF(OR(G16="",H16="",M16="",N16="",O16="",P16="",X16=""),"INCOMPLETO",IF(AI16<>"","REVISAR",IF(AND(AF16<>"",AG16="ESCANEADO"),"LISTO_COMPLETO","LISTO_SIN_BARCODE"))))) | AI16: =IF(NOT(OR(B16="EXISTENTE",COUNTA(G16,H16,I16,J16,K16,M16,N16,U16,V16,X16,Y16,Z16,AF16,AJ16)>0)),"",TEXTJOIN(" | ",TRUE,IF(A16="","Falta ID staging",""),IF(COUNTIF($A$5:$A$445,A16)>1,"ID staging duplicado",""),IF(G16="","Falta nombre",""),IF(LEN(G16)>150,"Nombre >150 caracteres",""),IF(H16="","Falta categoría",IF(COUNTIF(CategoriasLista,H16)=0,"Categoría inválida","")),IF(M16="","Falta precio compra",IF(OR(NOT(ISNUMBER(M16)),M16<0),"Precio compra inválido","")),IF(N16="","Falta precio venta",IF(OR(NOT(ISNUMBER(N16)),N16<=0,N16<M16),"Precio venta inválido","")),IF(O16="","Falta stock mínimo",IF(OR(NOT(ISNUMBER(O16)),O16<0,MOD(O16,1)<>0),"Stock mínimo inválido","")),IF(P16="","Falta unidad",IF(COUNTIF(UnidadesLista,P16)=0,"Unidad inválida","")),IF(AND(K16<>"",COUNTIF(ProveedoresLista,K16)=0),"Proveedor no catalogado",""),IF(X16="","Falta cantidad contada",IF(OR(NOT(ISNUMBER(X16)),X16<0,ABS(X16*1000-ROUND(X16*1000,0))>0.0000001),"Cantidad inválida",IF(AND(Q16="NO",MOD(X16,1)<>0),"Cantidad fraccionaria no permitida",""))),IF(AND(R16="SI",OR(NOT(ISNUMBER(S16)),S16<1,MOD(S16,1)<>0)),"Empaque inválido",""),IF(OR(AND(AF16="",AG16="ESCANEADO"),AND(AF16<>"",AG16<>"ESCANEADO")),"Barcode/estado inconsistente",""),IF(AK16<>"",AK16,""))) | AK16: =IF(G16="","",IF(OR(COUNTIFS($G$5:$G$445,G16,$I$5:$I$445,I16,$J$5:$J$445,J16,$P$5:$P$445,P16)>1,AND(AF16<>"",COUNTIF($AF$5:$AF$445,AF16)>1)),"REVISAR_POSIBLE_DUPLICADO",""))
A17: 6a0b3614-9eb5-5a78-9c9c-f6c7e9722810 | B17: EXISTENTE | C17: ACTIVO | D17: 13 | E17: 2d24ecb3-c7cd-4dee-9eaf-db968e844b8c | F17: TES-00013 | G17: ZZ_MULTIPC_8affe5 | H17: Test | M17: 100 | N17: 200 | O17: 1 | P17: UNIDAD | Q17: NO | R17: NO | S17: 1 | T17: NO | W17: 7 | AA17: =IF(X17="","",X17-IF(W17="",0,W17)) | AB17: =IF(OR(X17="",M17=""),"",X17*M17) | AC17: =IF(OR(X17="",N17=""),"",X17*N17) | AD17: =IF(OR(M17="",N17=""),"",N17-M17) | AE17: =IFERROR(IF(M17>0,(N17-M17)/M17,""),"") | AG17: PENDIENTE | AH17: =IF(NOT(OR(B17="EXISTENTE",COUNTA(G17,H17,I17,J17,K17,M17,N17,U17,V17,X17,Y17,Z17,AF17,AJ17)>0)),"",IF(AK17<>"","REVISAR",IF(OR(G17="",H17="",M17="",N17="",O17="",P17="",X17=""),"INCOMPLETO",IF(AI17<>"","REVISAR",IF(AND(AF17<>"",AG17="ESCANEADO"),"LISTO_COMPLETO","LISTO_SIN_BARCODE"))))) | AI17: =IF(NOT(OR(B17="EXISTENTE",COUNTA(G17,H17,I17,J17,K17,M17,N17,U17,V17,X17,Y17,Z17,AF17,AJ17)>0)),"",TEXTJOIN(" | ",TRUE,IF(A17="","Falta ID staging",""),IF(COUNTIF($A$5:$A$445,A17)>1,"ID staging duplicado",""),IF(G17="","Falta nombre",""),IF(LEN(G17)>150,"Nombre >150 caracteres",""),IF(H17="","Falta categoría",IF(COUNTIF(CategoriasLista,H17)=0,"Categoría inválida","")),IF(M17="","Falta precio compra",IF(OR(NOT(ISNUMBER(M17)),M17<0),"Precio compra inválido","")),IF(N17="","Falta precio venta",IF(OR(NOT(ISNUMBER(N17)),N17<=0,N17<M17),"Precio venta inválido","")),IF(O17="","Falta stock mínimo",IF(OR(NOT(ISNUMBER(O17)),O17<0,MOD(O17,1)<>0),"Stock mínimo inválido","")),IF(P17="","Falta unidad",IF(COUNTIF(UnidadesLista,P17)=0,"Unidad inválida","")),IF(AND(K17<>"",COUNTIF(ProveedoresLista,K17)=0),"Proveedor no catalogado",""),IF(X17="","Falta cantidad contada",IF(OR(NOT(ISNUMBER(X17)),X17<0,ABS(X17*1000-ROUND(X17*1000,0))>0.0000001),"Cantidad inválida",IF(AND(Q17="NO",MOD(X17,1)<>0),"Cantidad fraccionaria no permitida",""))),IF(AND(R17="SI",OR(NOT(ISNUMBER(S17)),S17<1,MOD(S17,1)<>0)),"Empaque inválido",""),IF(OR(AND(AF17="",AG17="ESCANEADO"),AND(AF17<>"",AG17<>"ESCANEADO")),"Barcode/estado inconsistente",""),IF(AK17<>"",AK17,""))) | AK17: =IF(G17="","",IF(OR(COUNTIFS($G$5:$G$445,G17,$I$5:$I$445,I17,$J$5:$J$445,J17,$P$5:$P$445,P17)>1,AND(AF17<>"",COUNTIF($AF$5:$AF$445,AF17)>1)),"REVISAR_POSIBLE_DUPLICADO",""))
A18: 3465d9a3-3023-5215-b6fa-6387f8712060 | B18: EXISTENTE | C18: ACTIVO | D18: 53 | E18: 23df1d6a-1f9d-481f-a495-5b803fb4eeca | F18: PRB-FER-0001 | G18: Tornillo drywall 6 x 1 pulgada | H18: Tornillería y fijaciones | I18: FixMaster | J18: Unidad | K18: Proveedor Prueba Ferretería Central S.A.S. | L18: 9 | M18: 180 | N18: 250 | O18: 160 | P18: UNIDAD | Q18: NO | R18: SI | S18: 100 | T18: SI | U18: Bodega de pruebas | V18: Producto ficticio de prueba para validacion de busquedas, inventario, ventas y compras en FERREPRO. No corresponde a inventario real. | W18: 800 | AA18: =IF(X18="","",X18-IF(W18="",0,W18)) | AB18: =IF(OR(X18="",M18=""),"",X18*M18) | AC18: =IF(OR(X18="",N18=""),"",X18*N18) | AD18: =IF(OR(M18="",N18=""),"",N18-M18) | AE18: =IFERROR(IF(M18>0,(N18-M18)/M18,""),"") | AG18: PENDIENTE | AH18: =IF(NOT(OR(B18="EXISTENTE",COUNTA(G18,H18,I18,J18,K18,M18,N18,U18,V18,X18,Y18,Z18,AF18,AJ18)>0)),"",IF(AK18<>"","REVISAR",IF(OR(G18="",H18="",M18="",N18="",O18="",P18="",X18=""),"INCOMPLETO",IF(AI18<>"","REVISAR",IF(AND(AF18<>"",AG18="ESCANEADO"),"LISTO_COMPLETO","LISTO_SIN_BARCODE"))))) | AI18: =IF(NOT(OR(B18="EXISTENTE",COUNTA(G18,H18,I18,J18,K18,M18,N18,U18,V18,X18,Y18,Z18,AF18,AJ18)>0)),"",TEXTJOIN(" | ",TRUE,IF(A18="","Falta ID staging",""),IF(COUNTIF($A$5:$A$445,A18)>1,"ID staging duplicado",""),IF(G18="","Falta nombre",""),IF(LEN(G18)>150,"Nombre >150 caracteres",""),IF(H18="","Falta categoría",IF(COUNTIF(CategoriasLista,H18)=0,"Categoría inválida","")),IF(M18="","Falta precio compra",IF(OR(NOT(ISNUMBER(M18)),M18<0),"Precio compra inválido","")),IF(N18="","Falta precio venta",IF(OR(NOT(ISNUMBER(N18)),N18<=0,N18<M18),"Precio venta inválido","")),IF(O18="","Falta stock mínimo",IF(OR(NOT(ISNUMBER(O18)),O18<0,MOD(O18,1)<>0),"Stock mínimo inválido","")),IF(P18="","Falta unidad",IF(COUNTIF(UnidadesLista,P18)=0,"Unidad inválida","")),IF(AND(K18<>"",COUNTIF(ProveedoresLista,K18)=0),"Proveedor no catalogado",""),IF(X18="","Falta cantidad contada",IF(OR(NOT(ISNUMBER(X18)),X18<0,ABS(X18*1000-ROUND(X18*1000,0))>0.0000001),"Cantidad inválida",IF(AND(Q18="NO",MOD(X18,1)<>0),"Cantidad fraccionaria no permitida",""))),IF(AND(R18="SI",OR(NOT(ISNUMBER(S18)),S18<1,MOD(S18,1)<>0)),"Empaque inválido",""),IF(OR(AND(AF18="",AG18="ESCANEADO"),AND(AF18<>"",AG18<>"ESCANEADO")),"Barcode/estado inconsistente",""),IF(AK18<>"",AK18,""))) | AK18: =IF(G18="","",IF(OR(COUNTIFS($G$5:$G$445,G18,$I$5:$I$445,I18,$J$5:$J$445,J18,$P$5:$P$445,P18)>1,AND(AF18<>"",COUNTIF($AF$5:$AF$445,AF18)>1)),"REVISAR_POSIBLE_DUPLICADO",""))
A19: 5b5e4e7b-c5eb-5a33-9919-0d81784b05a5 | B19: EXISTENTE | C19: ACTIVO | D19: 54 | E19: 5d4a6a2d-98b2-45bd-b60a-a8d49309e397 | F19: PRB-FER-0002 | G19: Tornillo drywall 6 x 1 1/2 pulgadas | H19: Tornillería y fijaciones | I19: FixMaster | J19: Unidad | K19: Proveedor Prueba ConstruMateriales del Norte | L19: 10 | M19: 230 | N19: 320 | O19: 150 | P19: UNIDAD | Q19: NO | R19: SI | S19: 100 | T19: SI | U19: Bodega de pruebas | V19: Producto ficticio de prueba para validacion de busquedas, inventario, ventas y compras en FERREPRO. No corresponde a inventario real. | W19: 750 | AA19: =IF(X19="","",X19-IF(W19="",0,W19)) | AB19: =IF(OR(X19="",M19=""),"",X19*M19) | AC19: =IF(OR(X19="",N19=""),"",X19*N19) | AD19: =IF(OR(M19="",N19=""),"",N19-M19) | AE19: =IFERROR(IF(M19>0,(N19-M19)/M19,""),"") | AG19: PENDIENTE | AH19: =IF(NOT(OR(B19="EXISTENTE",COUNTA(G19,H19,I19,J19,K19,M19,N19,U19,V19,X19,Y19,Z19,AF19,AJ19)>0)),"",IF(AK19<>"","REVISAR",IF(OR(G19="",H19="",M19="",N19="",O19="",P19="",X19=""),"INCOMPLETO",IF(AI19<>"","REVISAR",IF(AND(AF19<>"",AG19="ESCANEADO"),"LISTO_COMPLETO","LISTO_SIN_BARCODE"))))) | AI19: =IF(NOT(OR(B19="EXISTENTE",COUNTA(G19,H19,I19,J19,K19,M19,N19,U19,V19,X19,Y19,Z19,AF19,AJ19)>0)),"",TEXTJOIN(" | ",TRUE,IF(A19="","Falta ID staging",""),IF(COUNTIF($A$5:$A$445,A19)>1,"ID staging duplicado",""),IF(G19="","Falta nombre",""),IF(LEN(G19)>150,"Nombre >150 caracteres",""),IF(H19="","Falta categoría",IF(COUNTIF(CategoriasLista,H19)=0,"Categoría inválida","")),IF(M19="","Falta precio compra",IF(OR(NOT(ISNUMBER(M19)),M19<0),"Precio compra inválido","")),IF(N19="","Falta precio venta",IF(OR(NOT(ISNUMBER(N19)),N19<=0,N19<M19),"Precio venta inválido","")),IF(O19="","Falta stock mínimo",IF(OR(NOT(ISNUMBER(O19)),O19<0,MOD(O19,1)<>0),"Stock mínimo inválido","")),IF(P19="","Falta unidad",IF(COUNTIF(UnidadesLista,P19)=0,"Unidad inválida","")),IF(AND(K19<>"",COUNTIF(ProveedoresLista,K19)=0),"Proveedor no catalogado",""),IF(X19="","Falta cantidad contada",IF(OR(NOT(ISNUMBER(X19)),X19<0,ABS(X19*1000-ROUND(X19*1000,0))>0.0000001),"Cantidad inválida",IF(AND(Q19="NO",MOD(X19,1)<>0),"Cantidad fraccionaria no permitida",""))),IF(AND(R19="SI",OR(NOT(ISNUMBER(S19)),S19<1,MOD(S19,1)<>0)),"Empaque inválido",""),IF(OR(AND(AF19="",AG19="ESCANEADO"),AND(AF19<>"",AG19<>"ESCANEADO")),"Barcode/estado inconsistente",""),IF(AK19<>"",AK19,""))) | AK19: =IF(G19="","",IF(OR(COUNTIFS($G$5:$G$445,G19,$I$5:$I$445,I19,$J$5:$J$445,J19,$P$5:$P$445,P19)>1,AND(AF19<>"",COUNTIF($AF$5:$AF$445,AF19)>1)),"REVISAR_POSIBLE_DUPLICADO",""))
A20: 51b47958-b229-5296-8035-5db99e2e4592 | B20: EXISTENTE | C20: ACTIVO | D20: 55 | E20: 269534ab-f7b6-47d2-98b4-2302ae462b77 | F20: PRB-FER-0003 | G20: Tornillo autoperforante 8 x 1/2 | H20: Tornillería y fijaciones | I20: AceroPlus | J20: Unidad | K20: Proveedor Prueba Tornillos y Fijaciones Andinas | L20: 11 | M20: 250 | N20: 350 | O20: 130 | P20: UNIDAD | Q20: NO | R20: SI | S20: 100 | T20: SI | U20: Bodega de pruebas | V20: Producto ficticio de prueba para validacion de busquedas, inventario, ventas y compras en FERREPRO. No corresponde a inventario real. | W20: 650 | AA20: =IF(X20="","",X20-IF(W20="",0,W20)) | AB20: =IF(OR(X20="",M20=""),"",X20*M20) | AC20: =IF(OR(X20="",N20=""),"",X20*N20) | AD20: =IF(OR(M20="",N20=""),"",N20-M20) | AE20: =IFERROR(IF(M20>0,(N20-M20)/M20,""),"") | AG20: PENDIENTE | AH20: =IF(NOT(OR(B20="EXISTENTE",COUNTA(G20,H20,I20,J20,K20,M20,N20,U20,V20,X20,Y20,Z20,AF20,AJ20)>0)),"",IF(AK20<>"","REVISAR",IF(OR(G20="",H20="",M20="",N20="",O20="",P20="",X20=""),"INCOMPLETO",IF(AI20<>"","REVISAR",IF(AND(AF20<>"",AG20="ESCANEADO"),"LISTO_COMPLETO","LISTO_SIN_BARCODE"))))) | AI20: =IF(NOT(OR(B20="EXISTENTE",COUNTA(G20,H20,I20,J20,K20,M20,N20,U20,V20,X20,Y20,Z20,AF20,AJ20)>0)),"",TEXTJOIN(" | ",TRUE,IF(A20="","Falta ID staging",""),IF(COUNTIF($A$5:$A$445,A20)>1,"ID staging duplicado",""),IF(G20="","Falta nombre",""),IF(LEN(G20)>150,"Nombre >150 caracteres",""),IF(H20="","Falta categoría",IF(COUNTIF(CategoriasLista,H20)=0,"Categoría inválida","")),IF(M20="","Falta precio compra",IF(OR(NOT(ISNUMBER(M20)),M20<0),"Precio compra inválido","")),IF(N20="","Falta precio venta",IF(OR(NOT(ISNUMBER(N20)),N20<=0,N20<M20),"Precio venta inválido","")),IF(O20="","Falta stock mínimo",IF(OR(NOT(ISNUMBER(O20)),O20<0,MOD(O20,1)<>0),"Stock mínimo inválido","")),IF(P20="","Falta unidad",IF(COUNTIF(UnidadesLista,P20)=0,"Unidad inválida","")),IF(AND(K20<>"",COUNTIF(ProveedoresLista,K20)=0),"Proveedor no catalogado",""),IF(X20="","Falta cantidad contada",IF(OR(NOT(ISNUMBER(X20)),X20<0,ABS(X20*1000-ROUND(X20*1000,0))>0.0000001),"Cantidad inválida",IF(AND(Q20="NO",MOD(X20,1)<>0),"Cantidad fraccionaria no permitida",""))),IF(AND(R20="SI",OR(NOT(ISNUMBER(S20)),S20<1,MOD(S20,1)<>0)),"Empaque inválido",""),IF(OR(AND(AF20="",AG20="ESCANEADO"),AND(AF20<>"",AG20<>"ESCANEADO")),"Barcode/estado inconsistente",""),IF(AK20<>"",AK20,""))) | AK20: =IF(G20="","",IF(OR(COUNTIFS($G$5:$G$445,G20,$I$5:$I$445,I20,$J$5:$J$445,J20,$P$5:$P$445,P20)>1,AND(AF20<>"",COUNTIF($AF$5:$AF$445,AF20)>1)),"REVISAR_POSIBLE_DUPLICADO",""))
A21: 3e29d457-bc68-5cd9-9446-0960fdf4ca6c | B21: EXISTENTE | C21: ACTIVO | D21: 56 | E21: be1e6ca7-3d30-4412-b96e-a8ff03e933fd | F21: PRB-FER-0004 | G21: Tornillo madera 8 x 2 pulgadas | H21: Tornillería y fijaciones | I21: AceroPlus | J21: Unidad | K21: Proveedor Prueba Eléctricos Colombia | L21: 12 | M21: 320 | N21: 450 | O21: 120 | P21: UNIDAD | Q21: NO | R21: SI | S21: 100 | T21: SI | U21: Bodega de pruebas | V21: Producto ficticio de prueba para validacion de busquedas, inventario, ventas y compras en FERREPRO. No corresponde a inventario real. | W21: 600 | AA21: =IF(X21="","",X21-IF(W21="",0,W21)) | AB21: =IF(OR(X21="",M21=""),"",X21*M21) | AC21: =IF(OR(X21="",N21=""),"",X21*N21) | AD21: =IF(OR(M21="",N21=""),"",N21-M21) | AE21: =IFERROR(IF(M21>0,(N21-M21)/M21,""),"") | AG21: PENDIENTE | AH21: =IF(NOT(OR(B21="EXISTENTE",COUNTA(G21,H21,I21,J21,K21,M21,N21,U21,V21,X21,Y21,Z21,AF21,AJ21)>0)),"",IF(AK21<>"","REVISAR",IF(OR(G21="",H21="",M21="",N21="",O21="",P21="",X21=""),"INCOMPLETO",IF(AI21<>"","REVISAR",IF(AND(AF21<>"",AG21="ESCANEADO"),"LISTO_COMPLETO","LISTO_SIN_BARCODE"))))) | AI21: =IF(NOT(OR(B21="EXISTENTE",COUNTA(G21,H21,I21,J21,K21,M21,N21,U21,V21,X21,Y21,Z21,AF21,AJ21)>0)),"",TEXTJOIN(" | ",TRUE,IF(A21="","Falta ID staging",""),IF(COUNTIF($A$5:$A$445,A21)>1,"ID staging duplicado",""),IF(G21="","Falta nombre",""),IF(LEN(G21)>150,"Nombre >150 caracteres",""),IF(H21="","Falta categoría",IF(COUNTIF(CategoriasLista,H21)=0,"Categoría inválida","")),IF(M21="","Falta precio compra",IF(OR(NOT(ISNUMBER(M21)),M21<0),"Precio compra inválido","")),IF(N21="","Falta precio venta",IF(OR(NOT(ISNUMBER(N21)),N21<=0,N21<M21),"Precio venta inválido","")),IF(O21="","Falta stock mínimo",IF(OR(NOT(ISNUMBER(O21)),O21<0,MOD(O21,1)<>0),"Stock mínimo inválido","")),IF(P21="","Falta unidad",IF(COUNTIF(UnidadesLista,P21)=0,"Unidad inválida","")),IF(AND(K21<>"",COUNTIF(ProveedoresLista,K21)=0),"Proveedor no catalogado",""),IF(X21="","Falta cantidad contada",IF(OR(NOT(ISNUMBER(X21)),X21<0,ABS(X21*1000-ROUND(X21*1000,0))>0.0000001),"Cantidad inválida",IF(AND(Q21="NO",MOD(X21,1)<>0),"Cantidad fraccionaria no permitida",""))),IF(AND(R21="SI",OR(NOT(ISNUMBER(S21)),S21<1,MOD(S21,1)<>0)),"Empaque inválido",""),IF(OR(AND(AF21="",AG21="ESCANEADO"),AND(AF21<>"",AG21<>"ESCANEADO")),"Barcode/estado inconsistente",""),IF(AK21<>"",AK21,""))) | AK21: =IF(G21="","",IF(OR(COUNTIFS($G$5:$G$445,G21,$I$5:$I$445,I21,$J$5:$J$445,J21,$P$5:$P$445,P21)>1,AND(AF21<>"",COUNTIF($AF$5:$AF$445,AF21)>1)),"REVISAR_POSIBLE_DUPLICADO",""))
A22: e2eae5e7-84f2-523d-aca8-d947da7ca615 | B22: EXISTENTE | C22: ACTIVO | D22: 57 | E22: 6edfe94b-52ea-40b5-a8ca-86e90e36825e | F22: PRB-FER-0005 | G22: Tornillo zincado 10 x 1 pulgada | H22: Tornillería y fijaciones | I22: FerroMax | J22: Unidad | K22: Proveedor Prueba Pinturas y Acabados | L22: 13 | M22: 280 | N22: 400 | O22: 140 | P22: UNIDAD | Q22: NO | R22: SI | S22: 100 | T22: SI | U22: Bodega de pruebas | V22: Producto ficticio de prueba para validacion de busquedas, inventario, ventas y compras en FERREPRO. No corresponde a inventario real. | W22: 700 | AA22: =IF(X22="","",X22-IF(W22="",0,W22)) | AB22: =IF(OR(X22="",M22=""),"",X22*M22) | AC22: =IF(OR(X22="",N22=""),"",X22*N22) | AD22: =IF(OR(M22="",N22=""),"",N22-M22) | AE22: =IFERROR(IF(M22>0,(N22-M22)/M22,""),"") | AG22: PENDIENTE | AH22: =IF(NOT(OR(B22="EXISTENTE",COUNTA(G22,H22,I22,J22,K22,M22,N22,U22,V22,X22,Y22,Z22,AF22,AJ22)>0)),"",IF(AK22<>"","REVISAR",IF(OR(G22="",H22="",M22="",N22="",O22="",P22="",X22=""),"INCOMPLETO",IF(AI22<>"","REVISAR",IF(AND(AF22<>"",AG22="ESCANEADO"),"LISTO_COMPLETO","LISTO_SIN_BARCODE"))))) | AI22: =IF(NOT(OR(B22="EXISTENTE",COUNTA(G22,H22,I22,J22,K22,M22,N22,U22,V22,X22,Y22,Z22,AF22,AJ22)>0)),"",TEXTJOIN(" | ",TRUE,IF(A22="","Falta ID staging",""),IF(COUNTIF($A$5:$A$445,A22)>1,"ID staging duplicado",""),IF(G22="","Falta nombre",""),IF(LEN(G22)>150,"Nombre >150 caracteres",""),IF(H22="","Falta categoría",IF(COUNTIF(CategoriasLista,H22)=0,"Categoría inválida","")),IF(M22="","Falta precio compra",IF(OR(NOT(ISNUMBER(M22)),M22<0),"Precio compra inválido","")),IF(N22="","Falta precio venta",IF(OR(NOT(ISNUMBER(N22)),N22<=0,N22<M22),"Precio venta inválido","")),IF(O22="","Falta stock mínimo",IF(OR(NOT(ISNUMBER(O22)),O22<0,MOD(O22,1)<>0),"Stock mínimo inválido","")),IF(P22="","Falta unidad",IF(COUNTIF(UnidadesLista,P22)=0,"Unidad inválida","")),IF(AND(K22<>"",COUNTIF(ProveedoresLista,K22)=0),"Proveedor no catalogado",""),IF(X22="","Falta cantidad contada",IF(OR(NOT(ISNUMBER(X22)),X22<0,ABS(X22*1000-ROUND(X22*1000,0))>0.0000001),"Cantidad inválida",IF(AND(Q22="NO",MOD(X22,1)<>0),"Cantidad fraccionaria no permitida",""))),IF(AND(R22="SI",OR(NOT(ISNUMBER(S22)),S22<1,MOD(S22,1)<>0)),"Empaque inválido",""),IF(OR(AND(AF22="",AG22="ESCANEADO"),AND(AF22<>"",AG22<>"ESCANEADO")),"Barcode/estado inconsistente",""),IF(AK22<>"",AK22,""))) | AK22: =IF(G22="","",IF(OR(COUNTIFS($G$5:$G$445,G22,$I$5:$I$445,I22,$J$5:$J$445,J22,$P$5:$P$445,P22)>1,AND(AF22<>"",COUNTIF($AF$5:$AF$445,AF22)>1)),"REVISAR_POSIBLE_DUPLICADO",""))
A23: 9ff18e79-444a-5389-9562-22ac647dd4b6 | B23: EXISTENTE | C23: ACTIVO | D23: 58 | E23: e57bdb67-caee-45ca-b0a0-ef5cf8afaf55 | F23: PRB-FER-0006 | G23: Chazo plástico 1/4 | H23: Tornillería y fijaciones | I23: FixMaster | J23: Unidad | K23: Proveedor Prueba Herramientas Industriales | L23: 14 | M23: 120 | N23: 180 | O23: 200 | P23: UNIDAD | Q23: NO | R23: SI | S23: 50 | T23: SI | U23: Bodega de pruebas | V23: Producto ficticio de prueba para validacion de busquedas, inventario, ventas y compras en FERREPRO. No corresponde a inventario real. | W23: 1000 | AA23: =IF(X23="","",X23-IF(W23="",0,W23)) | AB23: =IF(OR(X23="",M23=""),"",X23*M23) | AC23: =IF(OR(X23="",N23=""),"",X23*N23) | AD23: =IF(OR(M23="",N23=""),"",N23-M23) | AE23: =IFERROR(IF(M23>0,(N23-M23)/M23,""),"") | AG23: PENDIENTE | AH23: =IF(NOT(OR(B23="EXISTENTE",COUNTA(G23,H23,I23,J23,K23,M23,N23,U23,V23,X23,Y23,Z23,AF23,AJ23)>0)),"",IF(AK23<>"","REVISAR",IF(OR(G23="",H23="",M23="",N23="",O23="",P23="",X23=""),"INCOMPLETO",IF(AI23<>"","REVISAR",IF(AND(AF23<>"",AG23="ESCANEADO"),"LISTO_COMPLETO","LISTO_SIN_BARCODE"))))) | AI23: =IF(NOT(OR(B23="EXISTENTE",COUNTA(G23,H23,I23,J23,K23,M23,N23,U23,V23,X23,Y23,Z23,AF23,AJ23)>0)),"",TEXTJOIN(" | ",TRUE,IF(A23="","Falta ID staging",""),IF(COUNTIF($A$5:$A$445,A23)>1,"ID staging duplicado",""),IF(G23="","Falta nombre",""),IF(LEN(G23)>150,"Nombre >150 caracteres",""),IF(H23="","Falta categoría",IF(COUNTIF(CategoriasLista,H23)=0,"Categoría inválida","")),IF(M23="","Falta precio compra",IF(OR(NOT(ISNUMBER(M23)),M23<0),"Precio compra inválido","")),IF(N23="","Falta precio venta",IF(OR(NOT(ISNUMBER(N23)),N23<=0,N23<M23),"Precio venta inválido","")),IF(O23="","Falta stock mínimo",IF(OR(NOT(ISNUMBER(O23)),O23<0,MOD(O23,1)<>0),"Stock mínimo inválido","")),IF(P23="","Falta unidad",IF(COUNTIF(UnidadesLista,P23)=0,"Unidad inválida","")),IF(AND(K23<>"",COUNTIF(ProveedoresLista,K23)=0),"Proveedor no catalogado",""),IF(X23="","Falta cantidad contada",IF(OR(NOT(ISNUMBER(X23)),X23<0,ABS(X23*1000-ROUND(X23*1000,0))>0.0000001),"Cantidad inválida",IF(AND(Q23="NO",MOD(X23,1)<>0),"Cantidad fraccionaria no permitida",""))),IF(AND(R23="SI",OR(NOT(ISNUMBER(S23)),S23<1,MOD(S23,1)<>0)),"Empaque inválido",""),IF(OR(AND(AF23="",AG23="ESCANEADO"),AND(AF23<>"",AG23<>"ESCANEADO")),"Barcode/estado inconsistente",""),IF(AK23<>"",AK23,""))) | AK23: =IF(G23="","",IF(OR(COUNTIFS($G$5:$G$445,G23,$I$5:$I$445,I23,$J$5:$J$445,J23,$P$5:$P$445,P23)>1,AND(AF23<>"",COUNTIF($AF$5:$AF$445,AF23)>1)),"REVISAR_POSIBLE_DUPLICADO",""))
A24: f48ca19b-0a13-5315-bd28-4cdb3d20af39 | B24: EXISTENTE | C24: ACTIVO | D24: 59 | E24: a25b5d2f-c152-40ed-a74d-f07a362f95b5 | F24: PRB-FER-0007 | G24: Chazo plástico 5/16 | H24: Tornillería y fijaciones | I24: FixMaster | J24: Unidad | K24: Proveedor Prueba Plomería Nacional | L24: 15 | M24: 160 | N24: 230 | O24: 180 | P24: UNIDAD | Q24: NO | R24: SI | S24: 50 | T24: SI | U24: Bodega de pruebas | V24: Producto ficticio de prueba para validacion de busquedas, inventario, ventas y compras en FERREPRO. No corresponde a inventario real. | W24: 900 | AA24: =IF(X24="","",X24-IF(W24="",0,W24)) | AB24: =IF(OR(X24="",M24=""),"",X24*M24) | AC24: =IF(OR(X24="",N24=""),"",X24*N24) | AD24: =IF(OR(M24="",N24=""),"",N24-M24) | AE24: =IFERROR(IF(M24>0,(N24-M24)/M24,""),"") | AG24: PENDIENTE | AH24: =IF(NOT(OR(B24="EXISTENTE",COUNTA(G24,H24,I24,J24,K24,M24,N24,U24,V24,X24,Y24,Z24,AF24,AJ24)>0)),"",IF(AK24<>"","REVISAR",IF(OR(G24="",H24="",M24="",N24="",O24="",P24="",X24=""),"INCOMPLETO",IF(AI24<>"","REVISAR",IF(AND(AF24<>"",AG24="ESCANEADO"),"LISTO_COMPLETO","LISTO_SIN_BARCODE"))))) | AI24: =IF(NOT(OR(B24="EXISTENTE",COUNTA(G24,H24,I24,J24,K24,M24,N24,U24,V24,X24,Y24,Z24,AF24,AJ24)>0)),"",TEXTJOIN(" | ",TRUE,IF(A24="","Falta ID staging",""),IF(COUNTIF($A$5:$A$445,A24)>1,"ID staging duplicado",""),IF(G24="","Falta nombre",""),IF(LEN(G24)>150,"Nombre >150 caracteres",""),IF(H24="","Falta categoría",IF(COUNTIF(CategoriasLista,H24)=0,"Categoría inválida","")),IF(M24="","Falta precio compra",IF(OR(NOT(ISNUMBER(M24)),M24<0),"Precio compra inválido","")),IF(N24="","Falta precio venta",IF(OR(NOT(ISNUMBER(N24)),N24<=0,N24<M24),"Precio venta inválido","")),IF(O24="","Falta stock mínimo",IF(OR(NOT(ISNUMBER(O24)),O24<0,MOD(O24,1)<>0),"Stock mínimo inválido","")),IF(P24="","Falta unidad",IF(COUNTIF(UnidadesLista,P24)=0,"Unidad inválida","")),IF(AND(K24<>"",COUNTIF(ProveedoresLista,K24)=0),"Proveedor no catalogado",""),IF(X24="","Falta cantidad contada",IF(OR(NOT(ISNUMBER(X24)),X24<0,ABS(X24*1000-ROUND(X24*1000,0))>0.0000001),"Cantidad inválida",IF(AND(Q24="NO",MOD(X24,1)<>0),"Cantidad fraccionaria no permitida",""))),IF(AND(R24="SI",OR(NOT(ISNUMBER(S24)),S24<1,MOD(S24,1)<>0)),"Empaque inválido",""),IF(OR(AND(AF24="",AG24="ESCANEADO"),AND(AF24<>"",AG24<>"ESCANEADO")),"Barcode/estado inconsistente",""),IF(AK24<>"",AK24,""))) | AK24: =IF(G24="","",IF(OR(COUNTIFS($G$5:$G$445,G24,$I$5:$I$445,I24,$J$5:$J$445,J24,$P$5:$P$445,P24)>1,AND(AF24<>"",COUNTIF($AF$5:$AF$445,AF24)>1)),"REVISAR_POSIBLE_DUPLICADO",""))
A25: cb4246bd-5af3-5d72-a090-eaccf0499b5b | B25: EXISTENTE | C25: ACTIVO | D25: 60 | E25: b4ba639d-6cf9-4ee2-8c6e-10d02eceaa23 | F25: PRB-FER-0008 | G25: Chazo expansivo metálico 3/8 | H25: Tornillería y fijaciones | I25: AceroPlus | J25: Unidad | K25: Proveedor Prueba Seguridad y Protección | L25: 16 | M25: 850 | N25: 1200 | O25: 60 | P25: UNIDAD | Q25: NO | R25: SI | S25: 50 | T25: SI | U25: Bodega de pruebas | V25: Producto ficticio de prueba para validacion de busquedas, inventario, ventas y compras en FERREPRO. No corresponde a inventario real. | W25: 300 | AA25: =IF(X25="","",X25-IF(W25="",0,W25)) | AB25: =IF(OR(X25="",M25=""),"",X25*M25) | AC25: =IF(OR(X25="",N25=""),"",X25*N25) | AD25: =IF(OR(M25="",N25=""),"",N25-M25) | AE25: =IFERROR(IF(M25>0,(N25-M25)/M25,""),"") | AG25: PENDIENTE | AH25: =IF(NOT(OR(B25="EXISTENTE",COUNTA(G25,H25,I25,J25,K25,M25,N25,U25,V25,X25,Y25,Z25,AF25,AJ25)>0)),"",IF(AK25<>"","REVISAR",IF(OR(G25="",H25="",M25="",N25="",O25="",P25="",X25=""),"INCOMPLETO",IF(AI25<>"","REVISAR",IF(AND(AF25<>"",AG25="ESCANEADO"),"LISTO_COMPLETO","LISTO_SIN_BARCODE"))))) | AI25: =IF(NOT(OR(B25="EXISTENTE",COUNTA(G25,H25,I25,J25,K25,M25,N25,U25,V25,X25,Y25,Z25,AF25,AJ25)>0)),"",TEXTJOIN(" | ",TRUE,IF(A25="","Falta ID staging",""),IF(COUNTIF($A$5:$A$445,A25)>1,"ID staging duplicado",""),IF(G25="","Falta nombre",""),IF(LEN(G25)>150,"Nombre >150 caracteres",""),IF(H25="","Falta categoría",IF(COUNTIF(CategoriasLista,H25)=0,"Categoría inválida","")),IF(M25="","Falta precio compra",IF(OR(NOT(ISNUMBER(M25)),M25<0),"Precio compra inválido","")),IF(N25="","Falta precio venta",IF(OR(NOT(ISNUMBER(N25)),N25<=0,N25<M25),"Precio venta inválido","")),IF(O25="","Falta stock mínimo",IF(OR(NOT(ISNUMBER(O25)),O25<0,MOD(O25,1)<>0),"Stock mínimo inválido","")),IF(P25="","Falta unidad",IF(COUNTIF(UnidadesLista,P25)=0,"Unidad inválida","")),IF(AND(K25<>"",COUNTIF(ProveedoresLista,K25)=0),"Proveedor no catalogado",""),IF(X25="","Falta cantidad contada",IF(OR(NOT(ISNUMBER(X25)),X25<0,ABS(X25*1000-ROUND(X25*1000,0))>0.0000001),"Cantidad inválida",IF(AND(Q25="NO",MOD(X25,1)<>0),"Cantidad fraccionaria no permitida",""))),IF(AND(R25="SI",OR(NOT(ISNUMBER(S25)),S25<1,MOD(S25,1)<>0)),"Empaque inválido",""),IF(OR(AND(AF25="",AG25="ESCANEADO"),AND(AF25<>"",AG25<>"ESCANEADO")),"Barcode/estado inconsistente",""),IF(AK25<>"",AK25,""))) | AK25: =IF(G25="","",IF(OR(COUNTIFS($G$5:$G$445,G25,$I$5:$I$445,I25,$J$5:$J$445,J25,$P$5:$P$445,P25)>1,AND(AF25<>"",COUNTIF($AF$5:$AF$445,AF25)>1)),"REVISAR_POSIBLE_DUPLICADO",""))
A26: 65b9f5e5-0b8d-576e-b85a-e4e73217fdfc | B26: EXISTENTE | C26: ACTIVO | D26: 61 | E26: 6d627067-0880-47f6-991a-d1fb753a2014 | F26: PRB-FER-0009 | G26: Puntilla con cabeza 1 pulgada | H26: Tornillería y fijaciones | I26: FerroMax | J26: Unidad | K26: Proveedor Prueba Ferretería Central S.A.S. | L26: 9 | M26: 90 | N26: 130 | O26: 200 | P26: UNIDAD | Q26: NO | R26: SI | S26: 100 | T26: SI | U26: Bodega de pruebas | V26: Producto ficticio de prueba para validacion de busquedas, inventario, ventas y compras en FERREPRO. No corresponde a inventario real. | W26: 1000 | AA26: =IF(X26="","",X26-IF(W26="",0,W26)) | AB26: =IF(OR(X26="",M26=""),"",X26*M26) | AC26: =IF(OR(X26="",N26=""),"",X26*N26) | AD26: =IF(OR(M26="",N26=""),"",N26-M26) | AE26: =IFERROR(IF(M26>0,(N26-M26)/M26,""),"") | AG26: PENDIENTE | AH26: =IF(NOT(OR(B26="EXISTENTE",COUNTA(G26,H26,I26,J26,K26,M26,N26,U26,V26,X26,Y26,Z26,AF26,AJ26)>0)),"",IF(AK26<>"","REVISAR",IF(OR(G26="",H26="",M26="",N26="",O26="",P26="",X26=""),"INCOMPLETO",IF(AI26<>"","REVISAR",IF(AND(AF26<>"",AG26="ESCANEADO"),"LISTO_COMPLETO","LISTO_SIN_BARCODE"))))) | AI26: =IF(NOT(OR(B26="EXISTENTE",COUNTA(G26,H26,I26,J26,K26,M26,N26,U26,V26,X26,Y26,Z26,AF26,AJ26)>0)),"",TEXTJOIN(" | ",TRUE,IF(A26="","Falta ID staging",""),IF(COUNTIF($A$5:$A$445,A26)>1,"ID staging duplicado",""),IF(G26="","Falta nombre",""),IF(LEN(G26)>150,"Nombre >150 caracteres",""),IF(H26="","Falta categoría",IF(COUNTIF(CategoriasLista,H26)=0,"Categoría inválida","")),IF(M26="","Falta precio compra",IF(OR(NOT(ISNUMBER(M26)),M26<0),"Precio compra inválido","")),IF(N26="","Falta precio venta",IF(OR(NOT(ISNUMBER(N26)),N26<=0,N26<M26),"Precio venta inválido","")),IF(O26="","Falta stock mínimo",IF(OR(NOT(ISNUMBER(O26)),O26<0,MOD(O26,1)<>0),"Stock mínimo inválido","")),IF(P26="","Falta unidad",IF(COUNTIF(UnidadesLista,P26)=0,"Unidad inválida","")),IF(AND(K26<>"",COUNTIF(ProveedoresLista,K26)=0),"Proveedor no catalogado",""),IF(X26="","Falta cantidad contada",IF(OR(NOT(ISNUMBER(X26)),X26<0,ABS(X26*1000-ROUND(X26*1000,0))>0.0000001),"Cantidad inválida",IF(AND(Q26="NO",MOD(X26,1)<>0),"Cantidad fraccionaria no permitida",""))),IF(AND(R26="SI",OR(NOT(ISNUMBER(S26)),S26<1,MOD(S26,1)<>0)),"Empaque inválido",""),IF(OR(AND(AF26="",AG26="ESCANEADO"),AND(AF26<>"",AG26<>"ESCANEADO")),"Barcode/estado inconsistente",""),IF(AK26<>"",AK26,""))) | AK26: =IF(G26="","",IF(OR(COUNTIFS($G$5:$G$445,G26,$I$5:$I$445,I26,$J$5:$J$445,J26,$P$5:$P$445,P26)>1,AND(AF26<>"",COUNTIF($AF$5:$AF$445,AF26)>1)),"REVISAR_POSIBLE_DUPLICADO",""))
A27: 189c5c81-441f-5f78-bbaf-4d2636cf1d1d | B27: EXISTENTE | C27: ACTIVO | D27: 62 | E27: 4cb027c1-2c12-4bac-89fd-b5afd383a9ce | F27: PRB-FER-0010 | G27: Puntilla con cabeza 2 pulgadas | H27: Tornillería y fijaciones | I27: FerroMax | J27: Unidad | K27: Proveedor Prueba ConstruMateriales del Norte | L27: 10 | M27: 130 | N27: 190 | O27: 190 | P27: UNIDAD | Q27: NO | R27: SI | S27: 100 | T27: SI | U27: Bodega de pruebas | V27: Producto ficticio de prueba para validacion de busquedas, inventario, ventas y compras en FERREPRO. No corresponde a inventario real. | W27: 950 | AA27: =IF(X27="","",X27-IF(W27="",0,W27)) | AB27: =IF(OR(X27="",M27=""),"",X27*M27) | AC27: =IF(OR(X27="",N27=""),"",X27*N27) | AD27: =IF(OR(M27="",N27=""),"",N27-M27) | AE27: =IFERROR(IF(M27>0,(N27-M27)/M27,""),"") | AG27: PENDIENTE | AH27: =IF(NOT(OR(B27="EXISTENTE",COUNTA(G27,H27,I27,J27,K27,M27,N27,U27,V27,X27,Y27,Z27,AF27,AJ27)>0)),"",IF(AK27<>"","REVISAR",IF(OR(G27="",H27="",M27="",N27="",O27="",P27="",X27=""),"INCOMPLETO",IF(AI27<>"","REVISAR",IF(AND(AF27<>"",AG27="ESCANEADO"),"LISTO_COMPLETO","LISTO_SIN_BARCODE"))))) | AI27: =IF(NOT(OR(B27="EXISTENTE",COUNTA(G27,H27,I27,J27,K27,M27,N27,U27,V27,X27,Y27,Z27,AF27,AJ27)>0)),"",TEXTJOIN(" | ",TRUE,IF(A27="","Falta ID staging",""),IF(COUNTIF($A$5:$A$445,A27)>1,"ID staging duplicado",""),IF(G27="","Falta nombre",""),IF(LEN(G27)>150,"Nombre >150 caracteres",""),IF(H27="","Falta categoría",IF(COUNTIF(CategoriasLista,H27)=0,"Categoría inválida","")),IF(M27="","Falta precio compra",IF(OR(NOT(ISNUMBER(M27)),M27<0),"Precio compra inválido","")),IF(N27="","Falta precio venta",IF(OR(NOT(ISNUMBER(N27)),N27<=0,N27<M27),"Precio venta inválido","")),IF(O27="","Falta stock mínimo",IF(OR(NOT(ISNUMBER(O27)),O27<0,MOD(O27,1)<>0),"Stock mínimo inválido","")),IF(P27="","Falta unidad",IF(COUNTIF(UnidadesLista,P27)=0,"Unidad inválida","")),IF(AND(K27<>"",COUNTIF(ProveedoresLista,K27)=0),"Proveedor no catalogado",""),IF(X27="","Falta cantidad contada",IF(OR(NOT(ISNUMBER(X27)),X27<0,ABS(X27*1000-ROUND(X27*1000,0))>0.0000001),"Cantidad inválida",IF(AND(Q27="NO",MOD(X27,1)<>0),"Cantidad fraccionaria no permitida",""))),IF(AND(R27="SI",OR(NOT(ISNUMBER(S27)),S27<1,MOD(S27,1)<>0)),"Empaque inválido",""),IF(OR(AND(AF27="",AG27="ESCANEADO"),AND(AF27<>"",AG27<>"ESCANEADO")),"Barcode/estado inconsistente",""),IF(AK27<>"",AK27,""))) | AK27: =IF(G27="","",IF(OR(COUNTIFS($G$5:$G$445,G27,$I$5:$I$445,I27,$J$5:$J$445,J27,$P$5:$P$445,P27)>1,AND(AF27<>"",COUNTIF($AF$5:$AF$445,AF27)>1)),"REVISAR_POSIBLE_DUPLICADO",""))
A28: 5dcb9fe2-6923-5eb0-a583-4969bd910c04 | B28: EXISTENTE | C28: ACTIVO | D28: 63 | E28: 8294c0af-ba38-43af-aa1d-a03a5f4b27fe | F28: PRB-FER-0011 | G28: Arandela plana 1/4 | H28: Tornillería y fijaciones | I28: AceroPlus | J28: Unidad | K28: Proveedor Prueba Tornillos y Fijaciones Andinas | L28: 11 | M28: 80 | N28: 120 | O28: 180 | P28: UNIDAD | Q28: NO | R28: SI | S28: 50 | T28: SI | U28: Bodega de pruebas | V28: Producto ficticio de prueba para validacion de busquedas, inventario, ventas y compras en FERREPRO. No corresponde a inventario real. | W28: 900 | AA28: =IF(X28="","",X28-IF(W28="",0,W28)) | AB28: =IF(OR(X28="",M28=""),"",X28*M28) | AC28: =IF(OR(X28="",N28=""),"",X28*N28) | AD28: =IF(OR(M28="",N28=""),"",N28-M28) | AE28: =IFERROR(IF(M28>0,(N28-M28)/M28,""),"") | AG28: PENDIENTE | AH28: =IF(NOT(OR(B28="EXISTENTE",COUNTA(G28,H28,I28,J28,K28,M28,N28,U28,V28,X28,Y28,Z28,AF28,AJ28)>0)),"",IF(AK28<>"","REVISAR",IF(OR(G28="",H28="",M28="",N28="",O28="",P28="",X28=""),"INCOMPLETO",IF(AI28<>"","REVISAR",IF(AND(AF28<>"",AG28="ESCANEADO"),"LISTO_COMPLETO","LISTO_SIN_BARCODE"))))) | AI28: =IF(NOT(OR(B28="EXISTENTE",COUNTA(G28,H28,I28,J28,K28,M28,N28,U28,V28,X28,Y28,Z28,AF28,AJ28)>0)),"",TEXTJOIN(" | ",TRUE,IF(A28="","Falta ID staging",""),IF(COUNTIF($A$5:$A$445,A28)>1,"ID staging duplicado",""),IF(G28="","Falta nombre",""),IF(LEN(G28)>150,"Nombre >150 caracteres",""),IF(H28="","Falta categoría",IF(COUNTIF(CategoriasLista,H28)=0,"Categoría inválida","")),IF(M28="","Falta precio compra",IF(OR(NOT(ISNUMBER(M28)),M28<0),"Precio compra inválido","")),IF(N28="","Falta precio venta",IF(OR(NOT(ISNUMBER(N28)),N28<=0,N28<M28),"Precio venta inválido","")),IF(O28="","Falta stock mínimo",IF(OR(NOT(ISNUMBER(O28)),O28<0,MOD(O28,1)<>0),"Stock mínimo inválido","")),IF(P28="","Falta unidad",IF(COUNTIF(UnidadesLista,P28)=0,"Unidad inválida","")),IF(AND(K28<>"",COUNTIF(ProveedoresLista,K28)=0),"Proveedor no catalogado",""),IF(X28="","Falta cantidad contada",IF(OR(NOT(ISNUMBER(X28)),X28<0,ABS(X28*1000-ROUND(X28*1000,0))>0.0000001),"Cantidad inválida",IF(AND(Q28="NO",MOD(X28,1)<>0),"Cantidad fraccionaria no permitida",""))),IF(AND(R28="SI",OR(NOT(ISNUMBER(S28)),S28<1,MOD(S28,1)<>0)),"Empaque inválido",""),IF(OR(AND(AF28="",AG28="ESCANEADO"),AND(AF28<>"",AG28<>"ESCANEADO")),"Barcode/estado inconsistente",""),IF(AK28<>"",AK28,""))) | AK28: =IF(G28="","",IF(OR(COUNTIFS($G$5:$G$445,G28,$I$5:$I$445,I28,$J$5:$J$445,J28,$P$5:$P$445,P28)>1,AND(AF28<>"",COUNTIF($AF$5:$AF$445,AF28)>1)),"REVISAR_POSIBLE_DUPLICADO",""))
